Workbook

Sheet 使用说明
A1: WMS 保税仓储管理系统 · 能力跟踪表
A2: 对齐项目设计十一大模块 + 公共框架 + 部署交付；生成日期 2026-09-21。本表是开发、前后端对接与测试的进度源，填「能力明细」即可，总览自动汇总。
A4: 一、工作表
A5: 项 | B5: 说明
A6: 使用说明 | B6: 状态口径、阶段算法、填写规则
A7: 进度总览 | B7: 按轨道 / 模块 / 批次自动汇总，含完成率；勿手改带公式的单元格
A8: 能力明细 | B8: 唯一填写入口。每行一条可独立验收的能力
A9: 页面对照 | B9: 原型页面 ↔ 模块 ↔ 能力条数，便于评审走查
A11: 二、六条进度轨道（从左到右）
A12: 项 | B12: 说明
A13: 原型设计 | B13: 可交互 HTML 原型（wms/dist）是否覆盖该能力。0 期已完成的业务项已预填「已完成」
A14: UI设计 | B14: UI设计.md 规范 + 原型视觉是否覆盖。已预填「已完成」
A15: 前端开发 | B15: 正式 React + TypeScript 实现（不含 HTML 原型）
A16: 后端开发 | B16: 正式 Java Spring Boot + Vastbase 实现
A17: 前后端对接 | B17: 联调通过：字段对齐、鉴权、错误码、分页/导出可用
A18: 测试 | B18: 按验收要点完成功能测试（含关键反向用例）并登记结果
A20: 三、状态取值（下拉，勿自造词）
A21: 项 | B21: 说明
A22: 未开始 | B22: 尚未投入该轨道
A23: 进行中 | B23: 正在做
A24: 已完成 | B24: 该轨道验收通过
A25: 阻塞 | B25: 做不下去，必须填「阻塞原因」
A26: 不适用 | B26: 该能力无此轨道（如纯后端的等保策略无 UI）
A28: 四、「阶段」列（自动，勿手改）
A29: 项 | B29: 说明
A30: 未开始 | B30: 六轨都未开始
A31: 原型中 / UI设计中 | B31: 仍在设计阶段
A32: 待开发 | B32: 原型+UI 已完成（或不适用），正式开发未开工 ← 当前大部分能力处于此阶段
A33: 开发中 | B33: 前端或后端已开工
A34: 对接中 | B34: 前后端均完成（或无需），正在联调
A35: 测试中 | B35: 联调完成，测试未完成
A36: 已完成 | B36: 六轨均为已完成或不适用
A37: 阻塞 | B37: 任一轨道为阻塞
A39: 五、填写规则
A40: 项 | B40: 说明
A41: 谁填 | B41: 前端填 前端开发；后端填 后端开发；联调双方共同填 前后端对接；测试填 测试。负责人三列按人填写
A42: 何时更新 | B42: 每条能力状态变化当日更新；每日站会看「进度总览」的阶段分布
A43: 完成标准 | B43: 前端完成 = 页面/交互按 UI 规范可演示（可用 Mock）；后端完成 = 接口可测且写入库规则正确；对接完成 = 去掉 Mock 走真实接口；测试完成 = 验收要点打勾
A44: 优先级 | B44: P0 主路径/合同验收必须；P1 完整交付；P2 扩展预留（园区/ERP/生产端口）
A45: 与合同节点 | B45: D10 第一批基础数据权限；D20 仓储主流程；D26 生产关务；D30 测评移交；D45 初验；D55 终验
...

Sheet 进度总览
A1: 进度总览（公式驱动，请勿在色块内手填）
A2: 完成率分母不含「不适用」。阶段分布来自「能力明细」的自动「阶段」列。
A4: 原型设计 | C4: UI设计 | E4: 前端开发 | G4: 后端开发 | I4: 前后端对接 | K4: 测试
A5: =IF((COUNTA(能力明细!J$2:J$154)-COUNTIF(能力明细!J$2:J$154,"不适用"))=0,"—",COUNTIF(能力明细!J$2:J$154,"已完成")/(COUNTA(能力明细!J$2:J$154)-COUNTIF(能力明细!J$2:J$154,"不适用"))) -> 1 | C5: =IF((COUNTA(能力明细!K$2:K$154)-COUNTIF(能力明细!K$2:K$154,"不适用"))=0,"—",COUNTIF(能力明细!K$2:K$154,"已完成")/(COUNTA(能力明细!K$2:K$154)-COUNTIF(能力明细!K$2:K$154,"不适用"))) -> 1 | E5: =IF((COUNTA(能力明细!L$2:L$154)-COUNTIF(能力明细!L$2:L$154,"不适用"))=0,"—",COUNTIF(能力明细!L$2:L$154,"已完成")/(COUNTA(能力明细!L$2:L$154)-COUNTIF(能力明细!L$2:L$154,"不适用"))) -> 0.013793103 | G5: =IF((COUNTA(能力明细!M$2:M$154)-COUNTIF(能力明细!M$2:M$154,"不适用"))=0,"—",COUNTIF(能力明细!M$2:M$154,"已完成")/(COUNTA(能力明细!M$2:M$154)-COUNTIF(能力明细!M$2:M$154,"不适用"))) -> 0 | I5: =IF((COUNTA(能力明细!N$2:N$154)-COUNTIF(能力明细!N$2:N$154,"不适用"))=0,"—",COUNTIF(能力明细!N$2:N$154,"已完成")/(COUNTA(能力明细!N$2:N$154)-COUNTIF(能力明细!N$2:N$154,"不适用"))) -> 0 | K5: =IF((COUNTA(能力明细!O$2:O$154)-COUNTIF(能力明细!O$2:O$154,"不适用"))=0,"—",COUNTIF(能力明细!O$2:O$154,"已完成")/(COUNTA(能力明细!O$2:O$154)-COUNTIF(能力明细!O$2:O$154,"不适用"))) -> 0
A6: =COUNTIF(能力明细!J$2:J$154,"已完成")&" 已完成 / "&(COUNTA(能力明细!J$2:J$154)-COUNTIF(能力明细!J$2:J$154,"不适用"))&" 适用" -> 138 已完成 / 138 适用 | C6: =COUNTIF(能力明细!K$2:K$154,"已完成")&" 已完成 / "&(COUNTA(能力明细!K$2:K$154)-COUNTIF(能力明细!K$2:K$154,"不适用"))&" 适用" -> 138 已完成 / 138 适用 | E6: =COUNTIF(能力明细!L$2:L$154,"已完成")&" 已完成 / "&(COUNTA(能力明细!L$2:L$154)-COUNTIF(能力明细!L$2:L$154,"不适用"))&" 适用" -> 2 已完成 / 145 适用 | G6: =COUNTIF(能力明细!M$2:M$154,"已完成")&" 已完成 / "&(COUNTA(能力明细!M$2:M$154)-COUNTIF(能力明细!M$2:M$154,"不适用"))&" 适用" -> 0 已完成 / 150 适用 | I6: =COUNTIF(能力明细!N$2:N$154,"已完成")&" 已完成 / "&(COUNTA(能力明细!N$2:N$154)-COUNTIF(能力明细!N$2:N$154,"不适用"))&" 适用" -> 0 已完成 / 147 适用 | K6: =COUNTIF(能力明细!O$2:O$154,"已完成")&" 已完成 / "&(COUNTA(能力明细!O$2:O$154)-COUNTIF(能力明细!O$2:O$154,"不适用"))&" 适用" -> 0 已完成 / 153 适用
A8: 阶段分布 | F8: 按模块
A9: 阶段 | B9: 条数 | C9: 占比 | D9: 说明 | F9: 模块 | G9: 能力数 | H9: 待开发 | I9: 开发中 | J9: 对接中 | K9: 测试中 | L9: 已完成
A10: 待开发 | B10: =COUNTIF(能力明细!P$2:P$154,A10) -> 151 | C10: =IF(COUNTA(能力明细!P$2:P$154)=0,0,B10/COUNTA(能力明细!P$2:P$154)) -> 0.9869281 | D10: 原型与 UI 已就绪，等待正式开发 | F10: 公共框架 | G10: =COUNTIF(能力明细!D$2:D$154,F10) -> 15 | H10: =COUNTIFS(能力明细!D$2:D$154,F10,能力明细!P$2:P$154,"待开发") -> 13 | I10: =COUNTIFS(能力明细!D$2:D$154,F10,能力明细!P$2:P$154,"开发中") -> 2 | J10: =COUNTIFS(能力明细!D$2:D$154,F10,能力明细!P$2:P$154,"对接中") -> 0 | K10: =COUNTIFS(能力明细!D$2:D$154,F10,能力明细!P$2:P$154,"测试中") -> 0 | L10: =COUNTIFS(能力明细!D$2:D$154,F10,能力明细!P$2:P$154,"已完成") -> 0
A11: 开发中 | B11: =COUNTIF(能力明细!P$2:P$154,A11) -> 2 | C11: =IF(COUNTA(能力明细!P$2:P$154)=0,0,B11/COUNTA(能力明细!P$2:P$154)) -> 0.013071895 | D11: 前端或后端已开工 | F11: 仓库管理 | G11: =COUNTIF(能力明细!D$2:D$154,F11) -> 3 | H11: =COUNTIFS(能力明细!D$2:D$154,F11,能力明细!P$2:P$154,"待开发") -> 3 | I11: =COUNTIFS(能力明细!D$2:D$154,F11,能力明细!P$2:P$154,"开发中") -> 0 | J11: =COUNTIFS(能力明细!D$2:D$154,F11,能力明细!P$2:P$154,"对接中") -> 0 | K11: =COUNTIFS(能力明细!D$2:D$154,F11,能力明细!P$2:P$154,"测试中") -> 0 | L11: =COUNTIFS(能力明细!D$2:D$154,F11,能力明细!P$2:P$154,"已完成") -> 0
A12: 对接中 | B12: =COUNTIF(能力明细!P$2:P$154,A12) -> 0 | C12: =IF(COUNTA(能力明细!P$2:P$154)=0,0,B12/COUNTA(能力明细!P$2:P$154)) -> 0 | D12: 前后端完成，正在联调 | F12: 堆位管理 | G12: =COUNTIF(能力明细!D$2:D$154,F12) -> 7 | H12: =COUNTIFS(能力明细!D$2:D$154,F12,能力明细!P$2:P$154,"待开发") -> 7 | I12: =COUNTIFS(能力明细!D$2:D$154,F12,能力明细!P$2:P$154,"开发中") -> 0 | J12: =COUNTIFS(能力明细!D$2:D$154,F12,能力明细!P$2:P$154,"对接中") -> 0 | K12: =COUNTIFS(能力明细!D$2:D$154,F12,能力明细!P$2:P$154,"测试中") -> 0 | L12: =COUNTIFS(能力明细!D$2:D$154,F12,能力明细!P$2:P$154,"已完成") -> 0
A13: 测试中 | B13: =COUNTIF(能力明细!P$2:P$154,A13) -> 0 | C13: =IF(COUNTA(能力明细!P$2:P$154)=0,0,B13/COUNTA(能力明细!P$2:P$154)) -> 0 | D13: 联调完成，测试进行中 | F13: 物料档案 | G13: =COUNTIF(能力明细!D$2:D$154,F13) -> 4 | H13: =COUNTIFS(能力明细!D$2:D$154,F13,能力明细!P$2:P$154,"待开发") -> 4 | I13: =COUNTIFS(能力明细!D$2:D$154,F13,能力明细!P$2:P$154,"开发中") -> 0 | J13: =COUNTIFS(能力明细!D$2:D$154,F13,能力明细!P$2:P$154,"对接中") -> 0 | K13: =COUNTIFS(能力明细!D$2:D$154,F13,能力明细!P$2:P$154,"测试中") -> 0 | L13: =COUNTIFS(能力明细!D$2:D$154,F13,能力明细!P$2:P$154,"已完成") -> 0
A14: 已完成 | B14: =COUNTIF(能力明细!P$2:P$154,A14) -> 0 | C14: =IF(COUNTA(能力明细!P$2:P$154)=0,0,B14/COUNTA(能力明细!P$2:P$154)) -> 0 | D14: 六轨均已完成或无需该轨 | F14: 矿源备案 | G14: =COUNTIF(能力明细!D$2:D$154,F14) -> 10 | H14: =COUNTIFS(能力明细!D$2:D$154,F14,能力明细!P$2:P$154,"待开发") -> 10 | I14: =COUNTIFS(能力明细!D$2:D$154,F14,能力明细!P$2:P$154,"开发中") -> 0 | J14: =COUNTIFS(能力明细!D$2:D$154,F14,能力明细!P$2:P$154,"对接中") -> 0 | K14: =COUNTIFS(能力明细!D$2:D$154,F14,能力明细!P$2:P$154,"测试中") -> 0 | L14: =COUNTIFS(能力明细!D$2:D$154,F14,能力明细!P$2:P$154,"已完成") -> 0
A15: 阻塞 | B15: =COUNTIF(能力明细!P$2:P$154,A15) -> 0 | C15: =IF(COUNTA(能力明细!P$2:P$154)=0,0,B15/COUNTA(能力明细!P$2:P$154)) -> 0 | D15: 存在阻塞，见明细「阻塞原因」 | F15: 往来主体 | G15: =COUNTIF(能力明细!D$2:D$154,F15) -> 3 | H15: =COUNTIFS(能力明细!D$2:D$154,F15,能力明细!P$2:P$154,"待开发") -> 3 | I15: =COUNTIFS(能力明细!D$2:D$154,F15,能力明细!P$2:P$154,"开发中") -> 0 | J15: =COUNTIFS(能力明细!D$2:D$154,F15,能力明细!P$2:P$154,"对接中") -> 0 | K15: =COUNTIFS(能力明细!D$2:D$154,F15,能力明细!P$2:P$154,"测试中") -> 0 | L15: =COUNTIFS(能力明细!D$2:D$154,F15,能力明细!P$2:P$154,"已完成") -> 0
A16: 未开始 | B16: =COUNTIF(能力明细!P$2:P$154,A16) -> 0 | C16: =IF(COUNTA(能力明细!P$2:P$154)=0,0,B16/COUNTA(能力明细!P$2:P$154)) -> 0 | D16: 设计尚未开始 | F16: 保税账册 | G16: =COUNTIF(能力明细!D$2:D$154,F16) -> 6 | H16: =COUNTIFS(能力明细!D$2:D$154,F16,能力明细!P$2:P$154,"待开发") -> 6 | I16: =COUNTIFS(能力明细!D$2:D$154,F16,能力明细!P$2:P$154,"开发中") -> 0 | J16: =COUNTIFS(能力明细!D$2:D$154,F16,能力明细!P$2:P$154,"对接中") -> 0 | K16: =COUNTIFS(能力明细!D$2:D$154,F16,能力明细!P$2:P$154,"测试中") -> 0 | L16: =COUNTIFS(能力明细!D$2:D$154,F16,能力明细!P$2:P$154,"已完成") -> 0
A17: 原型中 | B17: =COUNTIF(能力明细!P$2:P$154,A17) -> 0 | C17: =IF(COUNTA(能力明细!P$2:P$154)=0,0,B17/COUNTA(能力明细!P$2:P$154)) -> 0 | D17: 原型设计进行中 | F17: 系统设置 | G17: =COUNTIF(能力明细!D$2:D$154,F17) -> 8 | H17: =COUNTIFS(能力明细!D$2:D$154,F17,能力明细!P$2:P$154,"待开发") -> 8 | I17: =COUNTIFS(能力明细!D$2:D$154,F17,能力明细!P$2:P$154,"开发中") -> 0 | J17: =COUNTIFS(能力明细!D$2:D$154,F17,能力明细!P$2:P$154,"对接中") -> 0 | K17: =COUNTIFS(能力明细!D$2:D$154,F17,能力明细!P$2:P$154,"测试中") -> 0 | L17: =COUNTIFS(能力明细!D$2:D$154,F17,能力明细!P$2:P$154,"已完成") -> 0
A18: UI设计中 | B18: =COUNTIF(能力明细!P$2:P$154,A18) -> 0 | C18: =IF(COUNTA(能力明细!P$2:P$154)=0,0,B18/COUNTA(能力明细!P$2:P$154)) -> 0 | D18: UI 设计进行中 | F18: 平面图设置 | G18: =COUNTIF(能力明细!D$2:D$154,F18) -> 7 | H18: =COUNTIFS(能力明细!D$2:D$154,F18,能力明细!P$2:P$154,"待开发") -> 7 | I18: =COUNTIFS(能力明细!D$2:D$154,F18,能力明细!P$2:P$154,"开发中") -> 0 | J18: =COUNTIFS(能力明细!D$2:D$154,F18,能力明细!P$2:P$154,"对接中") -> 0 | K18: =COUNTIFS(能力明细!D$2:D$154,F18,能力明细!P$2:P$154,"测试中") -> 0 | L18: =COUNTIFS(能力明细!D$2:D$154,F18,能力明细!P$2:P$154,"已完成") -> 0
A19: 不适用 | B19: =COUNTIF(能力明细!P$2:P$154,A19) -> 0 | C19: =IF(COUNTA(能力明细!P$2:P$154)=0,0,B19/COUNTA(能力明细!P$2:P$154)) -> 0 | D19: 整行均为不适用（少见） | F19: 入库管理 | G19: =COUNTIF(能力明细!D$2:D$154,F19) -> 13 | H19: =COUNTIFS(能力明细!D$2:D$154,F19,能力明细!P$2:P$154,"待开发") -> 13 | I19: =COUNTIFS(能力明细!D$2:D$154,F19,能力明细!P$2:P$154,"开发中") -> 0 | J19: =COUNTIFS(能力明细!D$2:D$154,F19,能力明细!P$2:P$154,"对接中") -> 0 | K19: =COUNTIFS(能力明细!D$2:D$154,F19,能力明细!P$2:P$154,"测试中") -> 0 | L19: =COUNTIFS(能力明细!D$2:D$154,F19,能力明细!P$2:P$154,"已完成") -> 0
F20: 库内移库 | G20: =COUNTIF(能力明细!D$2:D$154,F20) -> 8 | H20: =COUNTIFS(能力明细!D$2:D$154,F20,能力明细!P$2:P$154,"待开发") -> 8 | I20: =COUNTIFS(能力明细!D$2:D$154,F20,能力明细!P$2:P$154,"开发中") -> 0 | J20: =COUNTIFS(能力明细!D$2:D$154,F20,能力明细!P$2:P$154,"对接中") -> 0 | K20: =COUNTIFS(能力明细!D$2:D$154,F20,能力明细!P$2:P$154,"测试中") -> 0 | L20: =COUNTIFS(能力明细!D$2:D$154,F20,能力明细!P$2:P$154,"已完成") -> 0
F21: 库存查询 | G21: =COUNTIF(能力明细!D$2:D$154,F21) -> 7 | H21: =COUNTIFS(能力明细!D$2:D$154,F21,能力明细!P$2:P$154,"待开发") -> 7 | I21: =COUNTIFS(能力明细!D$2:D$154,F21,能力明细!P$2:P$154,"开发中") -> 0 | J21: =COUNTIFS(能力明细!D$2:D$154,F21,能力明细!P$2:P$154,"对接中") -> 0 | K21: =COUNTIFS(能力明细!D$2:D$154,F21,能力明细!P$2:P$154,"测试中") -> 0 | L21: =COUNTIFS(能力明细!D$2:D$154,F21,能力明细!P$2:P$154,"已完成") -> 0
F22: 盘点管理 | G22: =COUNTIF(能力明细!D$2:D$154,F22) -> 3 | H22: =COUNTIFS(能力明细!D$2:D$154,F22,能力明细!P$2:P$154,"待开发") -> 3 | I22: =COUNTIFS(能力明细!D$2:D$154,F22,能力明细!P$2:P$154,"开发中") -> 0 | J22: =COUNTIFS(能力明细!D$2:D$154,F22,能力明细!P$2:P$154,"对接中") -> 0 | K22: =COUNTIFS(能力明细!D$2:D$154,F22,能力明细!P$2:P$154,"测试中") -> 0 | L22: =COUNTIFS(能力明细!D$2:D$154,F22,能力明细!P$2:P$154,"已完成") -> 0
F23: 库存预警 | G23: =COUNTIF(能力明细!D$2:D$154,F23) -> 4 | H23: =COUNTIFS(能力明细!D$2:D$154,F23,能力明细!P$2:P$154,"待开发") -> 4 | I23: =COUNTIFS(能力明细!D$2:D$154,F23,能力明细!P$2:P$154,"开发中") -> 0 | J23: =COUNTIFS(能力明细!D$2:D$154,F23,能力明细!P$2:P$154,"对接中") -> 0 | K23: =COUNTIFS(能力明细!D$2:D$154,F23,能力明细!P$2:P$154,"测试中") -> 0 | L23: =COUNTIFS(能力明细!D$2:D$154,F23,能力明细!P$2:P$154,"已完成") -> 0
F24: 出库管理 | G24: =COUNTIF(能力明细!D$2:D$154,F24) -> 7 | H24: =COUNTIFS(能力明细!D$2:D$154,F24,能力明细!P$2:P$154,"待开发") -> 7 | I24: =COUNTIFS(能力明细!D$2:D$154,F24,能力明细!P$2:P$154,"开发中") -> 0 | J24: =COUNTIFS(能力明细!D$2:D$154,F24,能力明细!P$2:P$154,"对接中") -> 0 | K24: =COUNTIFS(能力明细!D$2:D$154,F24,能力明细!P$2:P$154,"测试中") -> 0 | L24: =COUNTIFS(能力明细!D$2:D$154,F24,能力明细!P$2:P$154,"已完成") -> 0
F25: 生产完工 | G25: =COUNTIF(能力明细!D$2:D$154,F25) -> 8 | H25: =COUNTIFS(能力明细!D$2:D$154,F25,能力明细!P$2:P$154,"待开发") -> 8 | I25: =COUNTIFS(能力明细!D$2:D$154,F25,能力明细!P$2:P$154,"开发中") -> 0 | J25: =COUNTIFS(能力明细!D$2:D$154,F25,能力明细!P$2:P$154,"对接中") -> 0 | K25: =COUNTIFS(能力明细!D$2:D$154,F25,能力明细!P$2:P$154,"测试中") -> 0 | L25: =COUNTIFS(能力明细!D$2:D$154,F25,能力明细!P$2:P$154,"已完成") -> 0
F26: 关务保税 | G26: =COUNTIF(能力明细!D$2:D$154,F26) -> 6 | H26: =COUNTIFS(能力明细!D$2:D$154,F26,能力明细!P$2:P$154,"待开发") -> 6 | I26: =COUNTIFS(能力明细!D$2:D$154,F26,能力明细!P$2:P$154,"开发中") -> 0 | J26: =COUNTIFS(能力明细!D$2:D$154,F26,能力明细!P$2:P$154,"对接中") -> 0 | K26: =COUNTIFS(能力明细!D$2:D$154,F26,能力明细!P$2:P$154,"测试中") -> 0 | L26: =COUNTIFS(能力明细!D$2:D$154,F26,能力明细!P$2:P$154,"已完成") -> 0
F27: OCR识别 | G27: =COUNTIF(能力明细!D$2:D$154,F27) -> 7 | H27: =COUNTIFS(能力明细!D$2:D$154,F27,能力明细!P$2:P$154,"待开发") -> 7 | I27: =COUNTIFS(能力明细!D$2:D$154,F27,能力明细!P$2:P$154,"开发中") -> 0 | J27: =COUNTIFS(能力明细!D$2:D$154,F27,能力明细!P$2:P$154,"对接中") -> 0 | K27: =COUNTIFS(能力明细!D$2:D$154,F27,能力明细!P$2:P$154,"测试中") -> 0 | L27: =COUNTIFS(能力明细!D$2:D$154,F27,能力明细!P$2:P$154,"已完成") -> 0
F28: 对外对接 | G28: =COUNTIF(能力明细!D$2:D$154,F28) -> 7 | H28: =COUNTIFS(能力明细!D$2:D$154,F28,能力明细!P$2:P$154,"待开发") -> 7 | I28: =COUNTIFS(能力明细!D$2:D$154,F28,能力明细!P$2:P$154,"开发中") -> 0 | J28: =COUNTIFS(能力明细!D$2:D$154,F28,能力明细!P$2:P$154,"对接中") -> 0 | K28: =COUNTIFS(能力明细!D$2:D$154,F28,能力明细!P$2:P$154,"测试中") -> 0 | L28: =COUNTIFS(能力明细!D$2:D$154,F28,能力明细!P$2:P$154,"已完成") -> 0
F29: 操作日志 | G29: =COUNTIF(能力明细!D$2:D$154,F29) -> 3 | H29: =COUNTIFS(能力明细!D$2:D$154,F29,能力明细!P$2:P$154,"待开发") -> 3 | I29: =COUNTIFS(能力明细!D$2:D$154,F29,能力明细!P$2:P$154,"开发中") -> 0 | J29: =COUNTIFS(能力明细!D$2:D$154,F29,能力明细!P$2:P$154,"对接中") -> 0 | K29: =COUNTIFS(能力明细!D$2:D$154,F29,能力明细!P$2:P$154,"测试中") -> 0 | L29: =COUNTIFS(能力明细!D$2:D$154,F29,能力明细!P$2:P$154,"已完成") -> 0
F30: 可视化驾驶舱 | G30: =COUNTIF(能力明细!D$2:D$154,F30) -> 11 | H30: =COUNTIFS(能力明细!D$2:D$154,F30,能力明细!P$2:P$154,"待开发") -> 11 | I30: =COUNTIFS(能力明细!D$2:D$154,F30,能力明细!P$2:P$154,"开发中") -> 0 | J30: =COUNTIFS(能力明细!D$2:D$154,F30,能力明细!P$2:P$154,"对接中") -> 0 | K30: =COUNTIFS(能力明细!D$2:D$154,F30,能力明细!P$2:P$154,"测试中") -> 0 | L30: =COUNTIFS(能力明细!D$2:D$154,F30,能力明细!P$2:P$154,"已完成") -> 0
F31: 部署交付 | G31: =COUNTIF(能力明细!D$2:D$154,F31) -> 6 | H31: =COUNTIFS(能力明细!D$2:D$154,F31,能力明细!P$2:P$154,"待开发") -> 6 | I31: =COUNTIFS(能力明细!D$2:D$154,F31,能力明细!P$2:P$154,"开发中") -> 0 | J31: =COUNTIFS(能力明细!D$2:D$154,F31,能力明细!P$2:P$154,"对接中") -> 0 | K31: =COUNTIFS(能力明细!D$2:D$154,F31,能力明细!P$2:P$154,"测试中") -> 0 | L31: =COUNTIFS(能力明细!D$2:D$154,F31,能力明细!P$2:P$154,"已完成") -> 0
F32: 合计 | G32: =SUM(G10:G31) -> 153 | H32: =SUM(H10:H31) -> 151 | I32: =SUM(I10:I31) -> 2 | J32: =SUM(J10:J31) -> 0 | K32: =SUM(K10:K31) -> 0 | L32: =SUM(L10:L31) -> 0
F34: 提示：更新「能力明细」中 J–O 列状态后，本页数字与图表自动变化。P0 未完成不得宣称该批次可验收。
A36: 按交付批次
A37: 批次 | B37: 目标节点 | C37: 能力数 | D37: 待开发 | E37: 开发中 | F37: 对接中 | G37: 测试中 | H37: 已完成
A38: 启动 | B38: D5 | C38: =COUNTIF(能力明细!B$2:B$154,A38) -> 8 | D38: =COUNTIFS(能力明细!B$2:B$154,A38,能力明细!P$2:P$154,"待开发") -> 6 | E38: =COUNTIFS(能力明细!B$2:B$154,A38,能力明细!P$2:P$154,"开发中") -> 2 | F38: =COUNTIFS(能力明细!B$2:B$154,A38,能力明细!P$2:P$154,"对接中") -> 0 | G38: =COUNTIFS(能力明细!B$2:B$154,A38,能力明细!P$2:P$154,"测试中") -> 0 | H38: =COUNTIFS(能力明细!B$2:B$154,A38,能力明细!P$2:P$154,"已完成") -> 0
A39: 第一批 | B39: D10 | C39: =COUNTIF(能力明细!B$2:B$154,A39) -> 57 | D39: =COUNTIFS(能力明细!B$2:B$154,A39,能力明细!P$2:P$154,"待开发") -> 57 | E39: =COUNTIFS(能力明细!B$2:B$154,A39,能力明细!P$2:P$154,"开发中") -> 0 | F39: =COUNTIFS(能力明细!B$2:B$154,A39,能力明细!P$2:P$154,"对接中") -> 0 | G39: =COUNTIFS(能力明细!B$2:B$154,A39,能力明细!P$2:P$154,"测试中") -> 0 | H39: =COUNTIFS(能力明细!B$2:B$154,A39,能力明细!P$2:P$154,"已完成") -> 0
A40: 第二批 | B40: D20 | C40: =COUNTIF(能力明细!B$2:B$154,A40) -> 43 | D40: =COUNTIFS(能力明细!B$2:B$154,A40,能力明细!P$2:P$154,"待开发") -> 43 | E40: =COUNTIFS(能力明细!B$2:B$154,A40,能力明细!P$2:P$154,"开发中") -> 0 | F40: =COUNTIFS(能力明细!B$2:B$154,A40,能力明细!P$2:P$154,"对接中") -> 0 | G40: =COUNTIFS(能力明细!B$2:B$154,A40,能力明细!P$2:P$154,"测试中") -> 0 | H40: =COUNTIFS(能力明细!B$2:B$154,A40,能力明细!P$2:P$154,"已完成") -> 0
A41: 第三批 | B41: D26 | C41: =COUNTIF(能力明细!B$2:B$154,A41) -> 14 | D41: =COUNTIFS(能力明细!B$2:B$154,A41,能力明细!P$2:P$154,"待开发") -> 14 | E41: =COUNTIFS(能力明细!B$2:B$154,A41,能力明细!P$2:P$154,"开发中") -> 0 | F41: =COUNTIFS(能力明细!B$2:B$154,A41,能力明细!P$2:P$154,"对接中") -> 0 | G41: =COUNTIFS(能力明细!B$2:B$154,A41,能力明细!P$2:P$154,"测试中") -> 0 | H41: =COUNTIFS(能力明细!B$2:B$154,A41,能力明细!P$2:P$154,"已完成") -> 0
A42: 第四批 | B42: D30 | C42: =COUNTIF(能力明细!B$2:B$154,A42) -> 25 | D42: =COUNTIFS(能力明细!B$2:B$154,A42,能力明细!P$2:P$154,"待开发") -> 25 | E42: =COUNTIFS(能力明细!B$2:B$154,A42,能力明细!P$2:P$154,"开发中") -> 0 | F42: =COUNTIFS(能力明细!B$2:B$154,A42,能力明细!P$2:P$154,"对接中") -> 0 | G42: =COUNTIFS(能力明细!B$2:B$154,A42,能力明细!P$2:P$154,"测试中") -> 0 | H42: =COUNTIFS(能力明细!B$2:B$154,A42,能力明细!P$2:P$154,"已完成") -> 0
A43: 第五批 | B43: D45–D55 | C43: =COUNTIF(能力明细!B$2:B$154,A43) -> 6 | D43: =COUNTIFS(能力明细!B$2:B$154,A43,能力明细!P$2:P$154,"待开发") -> 6 | E43: =COUNTIFS(能力明细!B$2:B$154,A43,能力明细!P$2:P$154,"开发中") -> 0 | F43: =COUNTIFS(能力明细!B$2:B$154,A43,能力明细!P$2:P$154,"对接中") -> 0 | G43: =COUNTIFS(能力明细!B$2:B$154,A43,能力明细!P$2:P$154,"测试中") -> 0 | H43: =COUNTIFS(能力明细!B$2:B$154,A43,能力明细!P$2:P$154,"已完成") -> 0

Sheet 能力明细
A1: 编号 | B1: 交付批次 | C1: 目标节点 | D1: 模块 | E1: 页面 | F1: 能力名称 | G1: 能力说明 / 验收要点 | H1: 关联接口 | I1: 优先级 | J1: 原型设计 | K1: UI设计 | L1: 前端开发 | M1: 后端开发 | N1: 前后端对接 | O1: 测试 | P1: 阶段 | Q1: 前端负责人 | R1: 后端负责人 | S1: 测试负责人 | T1: 计划完成 | U1: 实际完成 | V1: 阻塞原因 | W1: 备注
A2: CAP-001 | B2: 启动 | C2: D5 | D2: 公共框架 | E2: 工程 | F2: 需求基线确认 | G2: 输出需求确认单、流程说明、数据字典、权限矩阵、接口清单并双方签字 | H2: — | I2: P0 | J2: 不适用 | K2: 不适用 | L2: 未开始 | M2: 未开始 | N2: 未开始 | O2: 未开始 | P2: =IF(COUNTIF(J2:O2,"阻塞")>0,"阻塞",IF(COUNTIFS(J2:O2,"<>已完成",J2:O2,"<>不适用")=0,"已完成",IF(OR(O2="进行中",AND(OR(L2="已完成",L2="不适用"),OR(M2="已完成",M2="不适用"),OR(N2="已完成",N2="不适用"),AND(O2<>"已完成",O2<>"不适用"),OR(L2="已完成",M2="已完成",N2="已完成"))),"测试中",IF(OR(N2="进行中",AND(OR(L2="已完成",L2="不适用"),OR(M2="已完成",M2="不适用"),AND(N2<>"已完成",N2<>"不适用"),OR(L2="已完成",M2="已完成"))),"对接中",IF(OR(L2="进行中",L2="已完成",M2="进行中",M2="已完成"),"开发中",IF(AND(OR(J2="已完成",J2="不适用"),OR(K2="已完成",K2="不适用")),"待开发",IF(K2="进行中","UI设计中",IF(OR(J2="进行中",J2="已完成"),"原型中","未开始")))))))) -> 待开发 | W2: 合同签订后 5 日内
A3: CAP-002 | B3: 启动 | C3: D5 | D3: 公共框架 | E3: 工程 | F3: 信创环境规划 | G3: 确认 CPU 架构、JDK 版本、Vastbase 实例授权与运行基线 | H3: — | I3: P0 | J3: 不适用 | K3: 不适用 | L3: 未开始 | M3: 未开始 | N3: 未开始 | O3: 未开始 | P3: =IF(COUNTIF(J3:O3,"阻塞")>0,"阻塞",IF(COUNTIFS(J3:O3,"<>已完成",J3:O3,"<>不适用")=0,"已完成",IF(OR(O3="进行中",AND(OR(L3="已完成",L3="不适用"),OR(M3="已完成",M3="不适用"),OR(N3="已完成",N3="不适用"),AND(O3<>"已完成",O3<>"不适用"),OR(L3="已完成",M3="已完成",N3="已完成"))),"测试中",IF(OR(N3="进行中",AND(OR(L3="已完成",L3="不适用"),OR(M3="已完成",M3="不适用"),AND(N3<>"已完成",N3<>"不适用"),OR(L3="已完成",M3="已完成"))),"对接中",IF(OR(L3="进行中",L3="已完成",M3="进行中",M3="已完成"),"开发中",IF(AND(OR(J3="已完成",J3="不适用"),OR(K3="已完成",K3="不适用")),"待开发",IF(K3="进行中","UI设计中",IF(OR(J3="进行中",J3="已完成"),"原型中","未开始")))))))) -> 待开发
A4: CAP-003 | B4: 启动 | C4: D5 | D4: 公共框架 | E4: 工程 | F4: 工程骨架可运行 | G4: Java Spring Boot + Flyway（PG 方言）+ JWT；前端登录鉴权、布局与权限路由 | H4: POST /api/auth/login | I4: P0 | J4: 不适用 | K4: 不适用 | L4: 未开始 | M4: 未开始 | N4: 未开始 | O4: 未开始 | P4: =IF(COUNTIF(J4:O4,"阻塞")>0,"阻塞",IF(COUNTIFS(J4:O4,"<>已完成",J4:O4,"<>不适用")=0,"已完成",IF(OR(O4="进行中",AND(OR(L4="已完成",L4="不适用"),OR(M4="已完成",M4="不适用"),OR(N4="已完成",N4="不适用"),AND(O4<>"已完成",O4<>"不适用"),OR(L4="已完成",M4="已完成",N4="已完成"))),"测试中",IF(OR(N4="进行中",AND(OR(L4="已完成",L4="不适用"),OR(M4="已完成",M4="不适用"),AND(N4<>"已完成",N4<>"不适用"),OR(L4="已完成",M4="已完成"))),"对接中",IF(OR(L4="进行中",L4="已完成",M4="进行中",M4="已完成"),"开发中",IF(AND(OR(J4="已完成",J4="不适用"),OR(K4="已完成",K4="不适用")),"待开发",IF(K4="进行中","UI设计中",IF(OR(J4="进行中",J4="已完成"),"原型中","未开始")))))))) -> 待开发
A5: CAP-004 | B5: 启动 | C5: D5 | D5: 公共框架 | E5: 登录 | F5: 多角色登录 | G5: 仓管员 / 关务员 / 管理员登录；按注册角色进入对应默认页 | H5: POST /api/auth/login | I5: P0 | J5: 已完成 | K5: 已完成 | L5: 未开始 | M5: 未开始 | N5: 未开始 | O5: 未开始 | P5: =IF(COUNTIF(J5:O5,"阻塞")>0,"阻塞",IF(COUNTIFS(J5:O5,"<>已完成",J5:O5,"<>不适用")=0,"已完成",IF(OR(O5="进行中",AND(OR(L5="已完成",L5="不适用"),OR(M5="已完成",M5="不适用"),OR(N5="已完成",N5="不适用"),AND(O5<>"已完成",O5<>"不适用"),OR(L5="已完成",M5="已完成",N5="已完成"))),"测试中",IF(OR(N5="进行中",AND(OR(L5="已完成",L5="不适用"),OR(M5="已完成",M5="不适用"),AND(N5<>"已完成",N5<>"不适用"),OR(L5="已完成",M5="已完成"))),"对接中",IF(OR(L5="进行中",L5="已完成",M5="进行中",M5="已完成"),"开发中",IF(AND(OR(J5="已完成",J5="不适用"),OR(K5="已完成",K5="不适用")),"待开发",IF(K5="进行中","UI设计中",IF(OR(J5="进行中",J5="已完成"),"原型中","未开始")))))))) -> 待开发
A6: CAP-005 | B6: 启动 | C6: D5 | D6: 公共框架 | E6: 登录 | F6: 登录态保持与退出 | G6: session 保持；退出清除令牌；角色切换刷新菜单 | H6: POST /api/auth/logout | I6: P0 | J6: 已完成 | K6: 已完成 | L6: 未开始 | M6: 未开始 | N6: 未开始 | O6: 未开始 | P6: =IF(COUNTIF(J6:O6,"阻塞")>0,"阻塞",IF(COUNTIFS(J6:O6,"<>已完成",J6:O6,"<>不适用")=0,"已完成",IF(OR(O6="进行中",AND(OR(L6="已完成",L6="不适用"),OR(M6="已完成",M6="不适用"),OR(N6="已完成",N6="不适用"),AND(O6<>"已完成",O6<>"不适用"),OR(L6="已完成",M6="已完成",N6="已完成"))),"测试中",IF(OR(N6="进行中",AND(OR(L6="已完成",L6="不适用"),OR(M6="已完成",M6="不适用"),AND(N6<>"已完成",N6<>"不适用"),OR(L6="已完成",M6="已完成"))),"对接中",IF(OR(L6="进行中",L6="已完成",M6="进行中",M6="已完成"),"开发中",IF(AND(OR(J6="已完成",J6="不适用"),OR(K6="已完成",K6="不适用")),"待开发",IF(K6="进行中","UI设计中",IF(OR(J6="进行中",J6="已完成"),"原型中","未开始")))))))) -> 待开发
A7: CAP-006 | B7: 启动 | C7: D5 | D7: 公共框架 | E7: 全局布局 | F7: 三栏布局与导航 | G7: 左侧导航 + 顶栏 + 内容区；侧栏分组：概览 / 基础数据 / 仓储作业 / 生产与关务 / 系统 | H7: — | I7: P0 | J7: 已完成 | K7: 已完成 | L7: 已完成 | M7: 未开始 | N7: 未开始 | O7: 未开始 | P7: =IF(COUNTIF(J7:O7,"阻塞")>0,"阻塞",IF(COUNTIFS(J7:O7,"<>已完成",J7:O7,"<>不适用")=0,"已完成",IF(OR(O7="进行中",AND(OR(L7="已完成",L7="不适用"),OR(M7="已完成",M7="不适用"),OR(N7="已完成",N7="不适用"),AND(O7<>"已完成",O7<>"不适用"),OR(L7="已完成",M7="已完成",N7="已完成"))),"测试中",IF(OR(N7="进行中",AND(OR(L7="已完成",L7="不适用"),OR(M7="已完成",M7="不适用"),AND(N7<>"已完成",N7<>"不适用"),OR(L7="已完成",M7="已完成"))),"对接中",IF(OR(L7="进行中",L7="已完成",M7="进行中",M7="已完成"),"开发中",IF(AND(OR(J7="已完成",J7="不适用"),OR(K7="已完成",K7="不适用")),"待开发",IF(K7="进行中","UI设计中",IF(OR(J7="进行中",J7="已完成"),"原型中","未开始")))))))) -> 开发中
A8: CAP-007 | B8: 启动 | C8: D5 | D8: 公共框架 | E8: 全局布局 | F8: 基础组件库 | G8: Button / Card / Input / Select / Modal / Toast / Badge / Table / Tabs / Upload / Empty / Loader | H8: — | I8: P0 | J8: 已完成 | K8: 已完成 | L8: 已完成 | M8: 未开始 | N8: 未开始 | O8: 未开始 | P8: =IF(COUNTIF(J8:O8,"阻塞")>0,"阻塞",IF(COUNTIFS(J8:O8,"<>已完成",J8:O8,"<>不适用")=0,"已完成",IF(OR(O8="进行中",AND(OR(L8="已完成",L8="不适用"),OR(M8="已完成",M8="不适用"),OR(N8="已完成",N8="不适用"),AND(O8<>"已完成",O8<>"不适用"),OR(L8="已完成",M8="已完成",N8="已完成"))),"测试中",IF(OR(N8="进行中",AND(OR(L8="已完成",L8="不适用"),OR(M8="已完成",M8="不适用"),AND(N8<>"已完成",N8<>"不适用"),OR(L8="已完成",M8="已完成"))),"对接中",IF(OR(L8="进行中",L8="已完成",M8="进行中",M8="已完成"),"开发中",IF(AND(OR(J8="已完成",J8="不适用"),OR(K8="已完成",K8="不适用")),"待开发",IF(K8="进行中","UI设计中",IF(OR(J8="进行中",J8="已完成"),"原型中","未开始")))))))) -> 开发中
A9: CAP-008 | B9: 启动 | C9: D5 | D9: 公共框架 | E9: 全局布局 | F9: 统一响应与错误提示 | G9: 接口统一 {success,data,message}；校验失败、权限不足、网络错误可感知 | H9: — | I9: P0 | J9: 不适用 | K9: 不适用 | L9: 未开始 | M9: 未开始 | N9: 未开始 | O9: 未开始 | P9: =IF(COUNTIF(J9:O9,"阻塞")>0,"阻塞",IF(COUNTIFS(J9:O9,"<>已完成",J9:O9,"<>不适用")=0,"已完成",IF(OR(O9="进行中",AND(OR(L9="已完成",L9="不适用"),OR(M9="已完成",M9="不适用"),OR(N9="已完成",N9="不适用"),AND(O9<>"已完成",O9<>"不适用"),OR(L9="已完成",M9="已完成",N9="已完成"))),"测试中",IF(OR(N9="进行中",AND(OR(L9="已完成",L9="不适用"),OR(M9="已完成",M9="不适用"),AND(N9<>"已完成",N9<>"不适用"),OR(L9="已完成",M9="已完成"))),"对接中",IF(OR(L9="进行中",L9="已完成",M9="进行中",M9="已完成"),"开发中",IF(AND(OR(J9="已完成",J9="不适用"),OR(K9="已完成",K9="不适用")),"待开发",IF(K9="进行中","UI设计中",IF(OR(J9="进行中",J9="已完成"),"原型中","未开始")))))))) -> 待开发
A10: CAP-009 | B10: 第一批 | C10: D10 | D10: 公共框架 | E10: 权限 | F10: 角色权限矩阵 | G10: 仓管员：入出库/移库/盘点/库存查询；关务员菜单默认全开；管理员全量含档案与设置 | H10: GET/PUT /api/roles/{id}/permissions | I10: P0 | J10: 已完成 | K10: 已完成 | L10: 未开始 | M10: 未开始 | N10: 未开始 | O10: 未开始 | P10: =IF(COUNTIF(J10:O10,"阻塞")>0,"阻塞",IF(COUNTIFS(J10:O10,"<>已完成",J10:O10,"<>不适用")=0,"已完成",IF(OR(O10="进行中",AND(OR(L10="已完成",L10="不适用"),OR(M10="已完成",M10="不适用"),OR(N10="已完成",N10="不适用"),AND(O10<>"已完成",O10<>"不适用"),OR(L10="已完成",M10="已完成",N10="已完成"))),"测试中",IF(OR(N10="进行中",AND(OR(L10="已完成",L10="不适用"),OR(M10="已完成",M10="不适用"),AND(N10<>"已完成",N10<>"不适用"),OR(L10="已完成",M10="已完成"))),"对接中",IF(OR(L10="进行中",L10="已完成",M10="进行中",M10="已完成"),"开发中",IF(AND(OR(J10="已完成",J10="不适用"),OR(K10="已完成",K10="不适用")),"待开发",IF(K10="进行中","UI设计中",IF(OR(J10="进行中",J10="已完成"),"原型中","未开始")))))))) -> 待开发
A11: CAP-010 | B11: 第一批 | C11: D10 | D11: 公共框架 | E11: 权限 | F11: 越权路由拦截 | G11: 前端藏菜单 + 后端接口级鉴权；无权限跳转默认页 | H11: — | I11: P0 | J11: 已完成 | K11: 已完成 | L11: 未开始 | M11: 未开始 | N11: 未开始 | O11: 未开始 | P11: =IF(COUNTIF(J11:O11,"阻塞")>0,"阻塞",IF(COUNTIFS(J11:O11,"<>已完成",J11:O11,"<>不适用")=0,"已完成",IF(OR(O11="进行中",AND(OR(L11="已完成",L11="不适用"),OR(M11="已完成",M11="不适用"),OR(N11="已完成",N11="不适用"),AND(O11<>"已完成",O11<>"不适用"),OR(L11="已完成",M11="已完成",N11="已完成"))),"测试中",IF(OR(N11="进行中",AND(OR(L11="已完成",L11="不适用"),OR(M11="已完成",M11="不适用"),AND(N11<>"已完成",N11<>"不适用"),OR(L11="已完成",M11="已完成"))),"对接中",IF(OR(L11="进行中",L11="已完成",M11="进行中",M11="已完成"),"开发中",IF(AND(OR(J11="已完成",J11="不适用"),OR(K11="已完成",K11="不适用")),"待开发",IF(K11="进行中","UI设计中",IF(OR(J11="进行中",J11="已完成"),"原型中","未开始")))))))) -> 待开发
A12: CAP-011 | B12: 第一批 | C12: D10 | D12: 公共框架 | E12: 权限 | F12: 海关专用账号审计标识 | G12: 关务员操作在审计日志中单独标识 | H12: GET /api/audit-logs | I12: P0 | J12: 已完成 | K12: 已完成 | L12: 未开始 | M12: 未开始 | N12: 未开始 | O12: 未开始 | P12: =IF(COUNTIF(J12:O12,"阻塞")>0,"阻塞",IF(COUNTIFS(J12:O12,"<>已完成",J12:O12,"<>不适用")=0,"已完成",IF(OR(O12="进行中",AND(OR(L12="已完成",L12="不适用"),OR(M12="已完成",M12="不适用"),OR(N12="已完成",N12="不适用"),AND(O12<>"已完成",O12<>"不适用"),OR(L12="已完成",M12="已完成",N12="已完成"))),"测试中",IF(OR(N12="进行中",AND(OR(L12="已完成",L12="不适用"),OR(M12="已完成",M12="不适用"),AND(N12<>"已完成",N12<>"不适用"),OR(L12="已完成",M12="已完成"))),"对接中",IF(OR(L12="进行中",L12="已完成",M12="进行中",M12="已完成"),"开发中",IF(AND(OR(J12="已完成",J12="不适用"),OR(K12="已完成",K12="不适用")),"待开发",IF(K12="进行中","UI设计中",IF(OR(J12="进行中",J12="已完成"),"原型中","未开始")))))))) -> 待开发
A13: CAP-012 | B13: 第一批 | C13: D10 | D13: 公共框架 | E13: 等保基线 | F13: 密码策略 | G13: 强密码规则（长度/复杂度），前后端双重校验 | H13: POST /api/auth/login | I13: P0 | J13: 不适用 | K13: 不适用 | L13: 未开始 | M13: 未开始 | N13: 未开始 | O13: 未开始 | P13: =IF(COUNTIF(J13:O13,"阻塞")>0,"阻塞",IF(COUNTIFS(J13:O13,"<>已完成",J13:O13,"<>不适用")=0,"已完成",IF(OR(O13="进行中",AND(OR(L13="已完成",L13="不适用"),OR(M13="已完成",M13="不适用"),OR(N13="已完成",N13="不适用"),AND(O13<>"已完成",O13<>"不适用"),OR(L13="已完成",M13="已完成",N13="已完成"))),"测试中",IF(OR(N13="进行中",AND(OR(L13="已完成",L13="不适用"),OR(M13="已完成",M13="不适用"),AND(N13<>"已完成",N13<>"不适用"),OR(L13="已完成",M13="已完成"))),"对接中",IF(OR(L13="进行中",L13="已完成",M13="进行中",M13="已完成"),"开发中",IF(AND(OR(J13="已完成",J13="不适用"),OR(K13="已完成",K13="不适用")),"待开发",IF(K13="进行中","UI设计中",IF(OR(J13="进行中",J13="已完成"),"原型中","未开始")))))))) -> 待开发
A14: CAP-013 | B14: 第一批 | C14: D10 | D14: 公共框架 | E14: 等保基线 | F14: 登录失败锁定 | G14: 连续失败锁定账号/IP，可配置阈值与时长 | H14: POST /api/auth/login | I14: P0 | J14: 不适用 | K14: 不适用 | L14: 未开始 | M14: 未开始 | N14: 未开始 | O14: 未开始 | P14: =IF(COUNTIF(J14:O14,"阻塞")>0,"阻塞",IF(COUNTIFS(J14:O14,"<>已完成",J14:O14,"<>不适用")=0,"已完成",IF(OR(O14="进行中",AND(OR(L14="已完成",L14="不适用"),OR(M14="已完成",M14="不适用"),OR(N14="已完成",N14="不适用"),AND(O14<>"已完成",O14<>"不适用"),OR(L14="已完成",M14="已完成",N14="已完成"))),"测试中",IF(OR(N14="进行中",AND(OR(L14="已完成",L14="不适用"),OR(M14="已完成",M14="不适用"),AND(N14<>"已完成",N14<>"不适用"),OR(L14="已完成",M14="已完成"))),"对接中",IF(OR(L14="进行中",L14="已完成",M14="进行中",M14="已完成"),"开发中",IF(AND(OR(J14="已完成",J14="不适用"),OR(K14="已完成",K14="不适用")),"待开发",IF(K14="进行中","UI设计中",IF(OR(J14="进行中",J14="已完成"),"原型中","未开始")))))))) -> 待开发
A15: CAP-014 | B15: 第一批 | C15: D10 | D15: 公共框架 | E15: 等保基线 | F15: 会话超时 | G15: 空闲超时自动退出并提示重新登录 | H15: — | I15: P0 | J15: 已完成 | K15: 已完成 | L15: 未开始 | M15: 未开始 | N15: 未开始 | O15: 未开始 | P15: =IF(COUNTIF(J15:O15,"阻塞")>0,"阻塞",IF(COUNTIFS(J15:O15,"<>已完成",J15:O15,"<>不适用")=0,"已完成",IF(OR(O15="进行中",AND(OR(L15="已完成",L15="不适用"),OR(M15="已完成",M15="不适用"),OR(N15="已完成",N15="不适用"),AND(O15<>"已完成",O15<>"不适用"),OR(L15="已完成",M15="已完成",N15="已完成"))),"测试中",IF(OR(N15="进行中",AND(OR(L15="已完成",L15="不适用"),OR(M15="已完成",M15="不适用"),AND(N15<>"已完成",N15<>"不适用"),OR(L15="已完成",M15="已完成"))),"对接中",IF(OR(L15="进行中",L15="已完成",M15="进行中",M15="已完成"),"开发中",IF(AND(OR(J15="已完成",J15="不适用"),OR(K15="已完成",K15="不适用")),"待开发",IF(K15="进行中","UI设计中",IF(OR(J15="进行中",J15="已完成"),"原型中","未开始")))))))) -> 待开发
A16: CAP-015 | B16: 第一批 | C16: D10 | D16: 公共框架 | E16: 工程 | F16: 信创最小冒烟 | G16: UOS Server + Vastbase 部署 Java 进程，完成登录 + 一条档案维护 | H16: GET /api/health | I16: P0 | J16: 不适用 | K16: 不适用 | L16: 未开始 | M16: 未开始 | N16: 未开始 | O16: 未开始 | P16: =IF(COUNTIF(J16:O16,"阻塞")>0,"阻塞",IF(COUNTIFS(J16:O16,"<>已完成",J16:O16,"<>不适用")=0,"已完成",IF(OR(O16="进行中",AND(OR(L16="已完成",L16="不适用"),OR(M16="已完成",M16="不适用"),OR(N16="已完成",N16="不适用"),AND(O16<>"已完成",O16<>"不适用"),OR(L16="已完成",M16="已完成",N16="已完成"))),"测试中",IF(OR(N16="进行中",AND(OR(L16="已完成",L16="不适用"),OR(M16="已完成",M16="不适用"),AND(N16<>"已完成",N16<>"不适用"),OR(L16="已完成",M16="已完成"))),"对接中",IF(OR(L16="进行中",L16="已完成",M16="进行中",M16="已完成"),"开发中",IF(AND(OR(J16="已完成",J16="不适用"),OR(K16="已完成",K16="不适用")),"待开发",IF(K16="进行中","UI设计中",IF(OR(J16="进行中",J16="已完成"),"原型中","未开始")))))))) -> 待开发 | W16: 开发便利环境与验收环境双轨
A17: CAP-016 | B17: 第一批 | C17: D10 | D17: 仓库管理 | E17: 仓库管理 | F17: 仓库列表 | G17: 展示 1/2/4/5/6 仓及码头仓库；编号、库容、面积㎡、堆位数、占用率、状态 | H17: GET /api/warehouses | I17: P0 | J17: 已完成 | K17: 已完成 | L17: 未开始 | M17: 未开始 | N17: 未开始 | O17: 未开始 | P17: =IF(COUNTIF(J17:O17,"阻塞")>0,"阻塞",IF(COUNTIFS(J17:O17,"<>已完成",J17:O17,"<>不适用")=0,"已完成",IF(OR(O17="进行中",AND(OR(L17="已完成",L17="不适用"),OR(M17="已完成",M17="不适用"),OR(N17="已完成",N17="不适用"),AND(O17<>"已完成",O17<>"不适用"),OR(L17="已完成",M17="已完成",N17="已完成"))),"测试中",IF(OR(N17="进行中",AND(OR(L17="已完成",L17="不适用"),OR(M17="已完成",M17="不适用"),AND(N17<>"已完成",N17<>"不适用"),OR(L17="已完成",M17="已完成"))),"对接中",IF(OR(L17="进行中",L17="已完成",M17="进行中",M17="已完成"),"开发中",IF(AND(OR(J17="已完成",J17="不适用"),OR(K17="已完成",K17="不适用")),"待开发",IF(K17="进行中","UI设计中",IF(OR(J17="进行中",J17="已完成"),"原型中","未开始")))))))) -> 待开发
A18: CAP-017 | B18: 第一批 | C18: D10 | D18: 仓库管理 | E18: 仓库管理 | F18: 仓库新建/编辑 | G18: 维护总库容与面积㎡；面积仅档案展示可编辑，不参与占用计算 | H18: POST /api/warehouses | I18: P0 | J18: 已完成 | K18: 已完成 | L18: 未开始 | M18: 未开始 | N18: 未开始 | O18: 未开始 | P18: =IF(COUNTIF(J18:O18,"阻塞")>0,"阻塞",IF(COUNTIFS(J18:O18,"<>已完成",J18:O18,"<>不适用")=0,"已完成",IF(OR(O18="进行中",AND(OR(L18="已完成",L18="不适用"),OR(M18="已完成",M18="不适用"),OR(N18="已完成",N18="不适用"),AND(O18<>"已完成",O18<>"不适用"),OR(L18="已完成",M18="已完成",N18="已完成"))),"测试中",IF(OR(N18="进行中",AND(OR(L18="已完成",L18="不适用"),OR(M18="已完成",M18="不适用"),AND(N18<>"已完成",N18<>"不适用"),OR(L18="已完成",M18="已完成"))),"对接中",IF(OR(L18="进行中",L18="已完成",M18="进行中",M18="已完成"),"开发中",IF(AND(OR(J18="已完成",J18="不适用"),OR(K18="已完成",K18="不适用")),"待开发",IF(K18="进行中","UI设计中",IF(OR(J18="进行中",J18="已完成"),"原型中","未开始")))))))) -> 待开发
A19: CAP-018 | B19: 第一批 | C19: D10 | D19: 仓库管理 | E19: 仓库管理 | F19: 仓库启停 | G19: 停用仓库不参与作业分配，平面图可标停用仓 | H19: POST /api/warehouses | I19: P1 | J19: 已完成 | K19: 已完成 | L19: 未开始 | M19: 未开始 | N19: 未开始 | O19: 未开始 | P19: =IF(COUNTIF(J19:O19,"阻塞")>0,"阻塞",IF(COUNTIFS(J19:O19,"<>已完成",J19:O19,"<>不适用")=0,"已完成",IF(OR(O19="进行中",AND(OR(L19="已完成",L19="不适用"),OR(M19="已完成",M19="不适用"),OR(N19="已完成",N19="不适用"),AND(O19<>"已完成",O19<>"不适用"),OR(L19="已完成",M19="已完成",N19="已完成"))),"测试中",IF(OR(N19="进行中",AND(OR(L19="已完成",L19="不适用"),OR(M19="已完成",M19="不适用"),AND(N19<>"已完成",N19<>"不适用"),OR(L19="已完成",M19="已完成"))),"对接中",IF(OR(L19="进行中",L19="已完成",M19="进行中",M19="已完成"),"开发中",IF(AND(OR(J19="已完成",J19="不适用"),OR(K19="已完成",K19="不适用")),"待开发",IF(K19="进行中","UI设计中",IF(OR(J19="进行中",J19="已完成"),"原型中","未开始")))))))) -> 待开发
A20: CAP-019 | B20: 第一批 | C20: D10 | D20: 堆位管理 | E20: 堆位管理 | F20: 堆位列表（单仓） | G20: 仅展示当前所选仓库（默认 1 仓）；编码、仓库、片区标识、网格、库容、状态 | H20: GET /api/warehouses/stacks | I20: P0 | J20: 已完成 | K20: 已完成 | L20: 未开始 | M20: 未开始 | N20: 未开始 | O20: 未开始 | P20: =IF(COUNTIF(J20:O20,"阻塞")>0,"阻塞",IF(COUNTIFS(J20:O20,"<>已完成",J20:O20,"<>不适用")=0,"已完成",IF(OR(O20="进行中",AND(OR(L20="已完成",L20="不适用"),OR(M20="已完成",M20="不适用"),OR(N20="已完成",N20="不适用"),AND(O20<>"已完成",O20<>"不适用"),OR(L20="已完成",M20="已完成",N20="已完成"))),"测试中",IF(OR(N20="进行中",AND(OR(L20="已完成",L20="不适用"),OR(M20="已完成",M20="不适用"),AND(N20<>"已完成",N20<>"不适用"),OR(L20="已完成",M20="已完成"))),"对接中",IF(OR(L20="进行中",L20="已完成",M20="进行中",M20="已完成"),"开发中",IF(AND(OR(J20="已完成",J20="不适用"),OR(K20="已完成",K20="不适用")),"待开发",IF(K20="进行中","UI设计中",IF(OR(J20="进行中",J20="已完成"),"原型中","未开始")))))))) -> 待开发
A21: CAP-020 | B21: 第一批 | C21: D10 | D21: 堆位管理 | E21: 堆位管理 | F21: 堆位新建/编辑 | G21: 编码由仓库编号+堆位名称自动拼接（如 1#A1）只读；不展示网格字段 | H21: POST /api/warehouses/stacks | I21: P0 | J21: 已完成 | K21: 已完成 | L21: 未开始 | M21: 未开始 | N21: 未开始 | O21: 未开始 | P21: =IF(COUNTIF(J21:O21,"阻塞")>0,"阻塞",IF(COUNTIFS(J21:O21,"<>已完成",J21:O21,"<>不适用")=0,"已完成",IF(OR(O21="进行中",AND(OR(L21="已完成",L21="不适用"),OR(M21="已完成",M21="不适用"),OR(N21="已完成",N21="不适用"),AND(O21<>"已完成",O21<>"不适用"),OR(L21="已完成",M21="已完成",N21="已完成"))),"测试中",IF(OR(N21="进行中",AND(OR(L21="已完成",L21="不适用"),OR(M21="已完成",M21="不适用"),AND(N21<>"已完成",N21<>"不适用"),OR(L21="已完成",M21="已完成"))),"对接中",IF(OR(L21="进行中",L21="已完成",M21="进行中",M21="已完成"),"开发中",IF(AND(OR(J21="已完成",J21="不适用"),OR(K21="已完成",K21="不适用")),"待开发",IF(K21="进行中","UI设计中",IF(OR(J21="进行中",J21="已完成"),"原型中","未开始")))))))) -> 待开发
A22: CAP-021 | B22: 第一批 | C22: D10 | D22: 堆位管理 | E22: 堆位管理 | F22: 档案字段收敛 | G22: 不展示报关单号、生产批次、占用率、查验状态 | H22: GET /api/warehouses/stacks | I22: P0 | J22: 已完成 | K22: 已完成 | L22: 未开始 | M22: 未开始 | N22: 未开始 | O22: 未开始 | P22: =IF(COUNTIF(J22:O22,"阻塞")>0,"阻塞",IF(COUNTIFS(J22:O22,"<>已完成",J22:O22,"<>不适用")=0,"已完成",IF(OR(O22="进行中",AND(OR(L22="已完成",L22="不适用"),OR(M22="已完成",M22="不适用"),OR(N22="已完成",N22="不适用"),AND(O22<>"已完成",O22<>"不适用"),OR(L22="已完成",M22="已完成",N22="已完成"))),"测试中",IF(OR(N22="进行中",AND(OR(L22="已完成",L22="不适用"),OR(M22="已完成",M22="不适用"),AND(N22<>"已完成",N22<>"不适用"),OR(L22="已完成",M22="已完成"))),"对接中",IF(OR(L22="进行中",L22="已完成",M22="进行中",M22="已完成"),"开发中",IF(AND(OR(J22="已完成",J22="不适用"),OR(K22="已完成",K22="不适用")),"待开发",IF(K22="进行中","UI设计中",IF(OR(J22="进行中",J22="已完成"),"原型中","未开始")))))))) -> 待开发
A23: CAP-022 | B23: 第一批 | C23: D10 | D23: 堆位管理 | E23: 堆位管理 | F23: 网格取自平面图 | G23: rows/cols 由园区平面图该堆位占格计算；列表只读展示 | H23: GET /api/floor-plans | I23: P0 | J23: 已完成 | K23: 已完成 | L23: 未开始 | M23: 未开始 | N23: 未开始 | O23: 未开始 | P23: =IF(COUNTIF(J23:O23,"阻塞")>0,"阻塞",IF(COUNTIFS(J23:O23,"<>已完成",J23:O23,"<>不适用")=0,"已完成",IF(OR(O23="进行中",AND(OR(L23="已完成",L23="不适用"),OR(M23="已完成",M23="不适用"),OR(N23="已完成",N23="不适用"),AND(O23<>"已完成",O23<>"不适用"),OR(L23="已完成",M23="已完成",N23="已完成"))),"测试中",IF(OR(N23="进行中",AND(OR(L23="已完成",L23="不适用"),OR(M23="已完成",M23="不适用"),AND(N23<>"已完成",N23<>"不适用"),OR(L23="已完成",M23="已完成"))),"对接中",IF(OR(L23="进行中",L23="已完成",M23="进行中",M23="已完成"),"开发中",IF(AND(OR(J23="已完成",J23="不适用"),OR(K23="已完成",K23="不适用")),"待开发",IF(K23="进行中","UI设计中",IF(OR(J23="进行中",J23="已完成"),"原型中","未开始")))))))) -> 待开发
A24: CAP-023 | B24: 第一批 | C24: D10 | D24: 堆位管理 | E24: 堆位管理 | F24: 片区标识三类 | G24: 仅原料区 / 待检区 / 成品区，随在库批次查验自动变更 | H24: PUT /api/warehouses/stacks/{id}/area-label | I24: P0 | J24: 已完成 | K24: 已完成 | L24: 未开始 | M24: 未开始 | N24: 未开始 | O24: 未开始 | P24: =IF(COUNTIF(J24:O24,"阻塞")>0,"阻塞",IF(COUNTIFS(J24:O24,"<>已完成",J24:O24,"<>不适用")=0,"已完成",IF(OR(O24="进行中",AND(OR(L24="已完成",L24="不适用"),OR(M24="已完成",M24="不适用"),OR(N24="已完成",N24="不适用"),AND(O24<>"已完成",O24<>"不适用"),OR(L24="已完成",M24="已完成",N24="已完成"))),"测试中",IF(OR(N24="进行中",AND(OR(L24="已完成",L24="不适用"),OR(M24="已完成",M24="不适用"),AND(N24<>"已完成",N24<>"不适用"),OR(L24="已完成",M24="已完成"))),"对接中",IF(OR(L24="进行中",L24="已完成",M24="进行中",M24="已完成"),"开发中",IF(AND(OR(J24="已完成",J24="不适用"),OR(K24="已完成",K24="不适用")),"待开发",IF(K24="进行中","UI设计中",IF(OR(J24="进行中",J24="已完成"),"原型中","未开始")))))))) -> 待开发
A25: CAP-024 | B25: 第一批 | C25: D10 | D25: 堆位管理 | E25: 堆位管理 | F25: 查验完成改成品区 | G25: 待检区堆位执行查验完成后改为成品区 | H25: PUT /api/warehouses/stacks/{id}/area-label | I25: P0 | J25: 已完成 | K25: 已完成 | L25: 未开始 | M25: 未开始 | N25: 未开始 | O25: 未开始 | P25: =IF(COUNTIF(J25:O25,"阻塞")>0,"阻塞",IF(COUNTIFS(J25:O25,"<>已完成",J25:O25,"<>不适用")=0,"已完成",IF(OR(O25="进行中",AND(OR(L25="已完成",L25="不适用"),OR(M25="已完成",M25="不适用"),OR(N25="已完成",N25="不适用"),AND(O25<>"已完成",O25<>"不适用"),OR(L25="已完成",M25="已完成",N25="已完成"))),"测试中",IF(OR(N25="进行中",AND(OR(L25="已完成",L25="不适用"),OR(M25="已完成",M25="不适用"),AND(N25<>"已完成",N25<>"不适用"),OR(L25="已完成",M25="已完成"))),"对接中",IF(OR(L25="进行中",L25="已完成",M25="进行中",M25="已完成"),"开发中",IF(AND(OR(J25="已完成",J25="不适用"),OR(K25="已完成",K25="不适用")),"待开发",IF(K25="进行中","UI设计中",IF(OR(J25="进行中",J25="已完成"),"原型中","未开始")))))))) -> 待开发
A26: CAP-025 | B26: 第一批 | C26: D10 | D26: 堆位管理 | E26: 堆位管理 | F26: 片区变更留痕 | G26: 片区标识变更写入操作日志（改前改后） | H26: GET /api/audit-logs | I26: P0 | J26: 已完成 | K26: 已完成 | L26: 未开始 | M26: 未开始 | N26: 未开始 | O26: 未开始 | P26: =IF(COUNTIF(J26:O26,"阻塞")>0,"阻塞",IF(COUNTIFS(J26:O26,"<>已完成",J26:O26,"<>不适用")=0,"已完成",IF(OR(O26="进行中",AND(OR(L26="已完成",L26="不适用"),OR(M26="已完成",M26="不适用"),OR(N26="已完成",N26="不适用"),AND(O26<>"已完成",O26<>"不适用"),OR(L26="已完成",M26="已完成",N26="已完成"))),"测试中",IF(OR(N26="进行中",AND(OR(L26="已完成",L26="不适用"),OR(M26="已完成",M26="不适用"),AND(N26<>"已完成",N26<>"不适用"),OR(L26="已完成",M26="已完成"))),"对接中",IF(OR(L26="进行中",L26="已完成",M26="进行中",M26="已完成"),"开发中",IF(AND(OR(J26="已完成",J26="不适用"),OR(K26="已完成",K26="不适用")),"待开发",IF(K26="进行中","UI设计中",IF(OR(J26="进行中",J26="已完成"),"原型中","未开始")))))))) -> 待开发
A27: CAP-026 | B27: 第一批 | C27: D10 | D27: 物料档案 | E27: 物料档案 | F27: 物料列表 | G27: 编码、名称、货物类型、类型、矿源 | H27: GET /api/materials | I27: P0 | J27: 已完成 | K27: 已完成 | L27: 未开始 | M27: 未开始 | N27: 未开始 | O27: 未开始 | P27: =IF(COUNTIF(J27:O27,"阻塞")>0,"阻塞",IF(COUNTIFS(J27:O27,"<>已完成",J27:O27,"<>不适用")=0,"已完成",IF(OR(O27="进行中",AND(OR(L27="已完成",L27="不适用"),OR(M27="已完成",M27="不适用"),OR(N27="已完成",N27="不适用"),AND(O27<>"已完成",O27<>"不适用"),OR(L27="已完成",M27="已完成",N27="已完成"))),"测试中",IF(OR(N27="进行中",AND(OR(L27="已完成",L27="不适用"),OR(M27="已完成",M27="不适用"),AND(N27<>"已完成",N27<>"不适用"),OR(L27="已完成",M27="已完成"))),"对接中",IF(OR(L27="进行中",L27="已完成",M27="进行中",M27="已完成"),"开发中",IF(AND(OR(J27="已完成",J27="不适用"),OR(K27="已完成",K27="不适用")),"待开发",IF(K27="进行中","UI设计中",IF(OR(J27="进行中",J27="已完成"),"原型中","未开始")))))))) -> 待开发
A28: CAP-027 | B28: 第一批 | C28: D10 | D28: 物料档案 | E28: 物料档案 | F28: 新建/编辑仅基础信息 | G28: 仅编码、名称、货物类型、类型；报备矿填矿源。不含干湿重规则、默认账册、单证样例、原产国、品质参数、附件 | H28: POST /api/materials | I28: P0 | J28: 已完成 | K28: 已完成 | L28: 未开始 | M28: 未开始 | N28: 未开始 | O28: 未开始 | P28: =IF(COUNTIF(J28:O28,"阻塞")>0,"阻塞",IF(COUNTIFS(J28:O28,"<>已完成",J28:O28,"<>不适用")=0,"已完成",IF(OR(O28="进行中",AND(OR(L28="已完成",L28="不适用"),OR(M28="已完成",M28="不适用"),OR(N28="已完成",N28="不适用"),AND(O28<>"已完成",O28<>"不适用"),OR(L28="已完成",M28="已完成",N28="已完成"))),"测试中",IF(OR(N28="进行中",AND(OR(L28="已完成",L28="不适用"),OR(M28="已完成",M28="不适用"),AND(N28<>"已完成",N28<>"不适用"),OR(L28="已完成",M28="已完成"))),"对接中",IF(OR(L28="进行中",L28="已完成",M28="进行中",M28="已完成"),"开发中",IF(AND(OR(J28="已完成",J28="不适用"),OR(K28="已完成",K28="不适用")),"待开发",IF(K28="进行中","UI设计中",IF(OR(J28="进行中",J28="已完成"),"原型中","未开始")))))))) -> 待开发
... A32: CAP-031 | B32: 第一批 | C32: D10 | D32: 矿源备案 | E32: 物料档案 / 矿源备案 | F32: 备案列表筛选 | G32: 按矿源、编号、状态、备案日期起止查询 | H32: GET /api/material-sources/filings | I32: P0 | J32: 已完成 | K32: 已完成 | L32: 未开始 | M32: 未开始 | N32: 未开始 | O32: 未开始 | P32: =IF(COUNTIF(J32:O32,"阻塞")>0,"阻塞",IF(COUNTIFS(J32:O32,"<>已完成",J32:O32,"<>不适用")=0,"已完成",IF(OR(O32="进行中",AND(OR(L32="已完成",L32="不适用"),OR(M32="已完成",M32="不适用"),OR(N32="已完成",N32="不适用"),AND(O32<>"已完成",O32<>"不适用"),OR(L32="已完成",M32="已完成",N32="已完成"))),"测试中",IF(OR(N32="进行中",AND(OR(L32="已完成",L32="不适用"),OR(M32="已完成",M32="不适用"),AND(N32<>"已完成",N32<>"不适用"),OR(L32="已完成",M32="已完成"))),"对接中",IF(OR(L32="进行中",L32="已完成",M32="进行中",M32="已完成"),"开发中",IF(AND(OR(J32="已完成",J32="不适用"),OR(K32="已完成",K32="不适用")),"待开发",IF(K32="进行中","UI设计中",IF(OR(J32="进行中",J32="已完成"),"原型中","未开始")))))))) -> 待开发
A33: CAP-032 | B33: 第一批 | C33: D10 | D33: 矿源备案 | E33: 物料档案 / 矿源备案 | F33: 点击编号查看票货 | G33: 该备案下全部票货：报关单号、生产批次号、委托方、重量、堆位、状态 | H33: GET /api/material-sources/filings/{code}/lots | I33: P0 | J33: 已完成 | K33: 已完成 | L33: 未开始 | M33: 未开始 | N33: 未开始 | O33: 未开始 | P33: =IF(COUNTIF(J33:O33,"阻塞")>0,"阻塞",IF(COUNTIFS(J33:O33,"<>已完成",J33:O33,"<>不适用")=0,"已完成",IF(OR(O33="进行中",AND(OR(L33="已完成",L33="不适用"),OR(M33="已完成",M33="不适用"),OR(N33="已完成",N33="不适用"),AND(O33<>"已完成",O33<>"不适用"),OR(L33="已完成",M33="已完成",N33="已完成"))),"测试中",IF(OR(N33="进行中",AND(OR(L33="已完成",L33="不适用"),OR(M33="已完成",M33="不适用"),AND(N33<>"已完成",N33<>"不适用"),OR(L33="已完成",M33="已完成"))),"对接中",IF(OR(L33="进行中",L33="已完成",M33="进行中",M33="已完成"),"开发中",IF(AND(OR(J33="已完成",J33="不适用"),OR(K33="已完成",K33="不适用")),"待开发",IF(K33="进行中","UI设计中",IF(OR(J33="进行中",J33="已完成"),"原型中","未开始")))))))) -> 待开发 | W33: 待确认：详情「已核销」指生产消耗还是成品完整出库
A34: CAP-033 | B34: 第一批 | C34: D10 | D34: 矿源备案 | E34: 物料档案 / 矿源备案 | F34: 备案列表导出 | G34: 矿源备案列表导出 Excel | H34: GET /api/material-sources/filings/export | I34: P1 | J34: 已完成 | K34: 已完成 | L34: 未开始 | M34: 未开始 | N34: 未开始 | O34: 未开始 | P34: =IF(COUNTIF(J34:O34,"阻塞")>0,"阻塞",IF(COUNTIFS(J34:O34,"<>已完成",J34:O34,"<>不适用")=0,"已完成",IF(OR(O34="进行中",AND(OR(L34="已完成",L34="不适用"),OR(M34="已完成",M34="不适用"),OR(N34="已完成",N34="不适用"),AND(O34<>"已完成",O34<>"不适用"),OR(L34="已完成",M34="已完成",N34="已完成"))),"测试中",IF(OR(N34="进行中",AND(OR(L34="已完成",L34="不适用"),OR(M34="已完成",M34="不适用"),AND(N34<>"已完成",N34<>"不适用"),OR(L34="已完成",M34="已完成"))),"对接中",IF(OR(L34="进行中",L34="已完成",M34="进行中",M34="已完成"),"开发中",IF(AND(OR(J34="已完成",J34="不适用"),OR(K34="已完成",K34="不适用")),"待开发",IF(K34="进行中","UI设计中",IF(OR(J34="进行中",J34="已完成"),"原型中","未开始")))))))) -> 待开发
A35: CAP-034 | B35: 第一批 | C35: D10 | D35: 矿源备案 | E35: 物料档案 / 矿源备案 | F35: 票货导出 | G35: 备案下全部票货导出 Excel | H35: GET /api/material-sources/filings/{code}/lots/export | I35: P1 | J35: 已完成 | K35: 已完成 | L35: 未开始 | M35: 未开始 | N35: 未开始 | O35: 未开始 | P35: =IF(COUNTIF(J35:O35,"阻塞")>0,"阻塞",IF(COUNTIFS(J35:O35,"<>已完成",J35:O35,"<>不适用")=0,"已完成",IF(OR(O35="进行中",AND(OR(L35="已完成",L35="不适用"),OR(M35="已完成",M35="不适用"),OR(N35="已完成",N35="不适用"),AND(O35<>"已完成",O35<>"不适用"),OR(L35="已完成",M35="已完成",N35="已完成"))),"测试中",IF(OR(N35="进行中",AND(OR(L35="已完成",L35="不适用"),OR(M35="已完成",M35="不适用"),AND(N35<>"已完成",N35<>"不适用"),OR(L35="已完成",M35="已完成"))),"对接中",IF(OR(L35="进行中",L35="已完成",M35="进行中",M35="已完成"),"开发中",IF(AND(OR(J35="已完成",J35="不适用"),OR(K35="已完成",K35="不适用")),"待开发",IF(K35="进行中","UI设计中",IF(OR(J35="进行中",J35="已完成"),"原型中","未开始")))))))) -> 待开发
A36: CAP-035 | B36: 第一批 | C36: D10 | D36: 矿源备案 | E36: 物料档案 / 矿源备案 | F36: 入库自动匹配备案号 | G36: 报备矿入库按矿源自动匹配当前有效且有剩余的备案号 | H36: POST /api/inbound | I36: P0 | J36: 已完成 | K36: 已完成 | L36: 未开始 | M36: 未开始 | N36: 未开始 | O36: 未开始 | P36: =IF(COUNTIF(J36:O36,"阻塞")>0,"阻塞",IF(COUNTIFS(J36:O36,"<>已完成",J36:O36,"<>不适用")=0,"已完成",IF(OR(O36="进行中",AND(OR(L36="已完成",L36="不适用"),OR(M36="已完成",M36="不适用"),OR(N36="已完成",N36="不适用"),AND(O36<>"已完成",O36<>"不适用"),OR(L36="已完成",M36="已完成",N36="已完成"))),"测试中",IF(OR(N36="进行中",AND(OR(L36="已完成",L36="不适用"),OR(M36="已完成",M36="不适用"),AND(N36<>"已完成",N36<>"不适用"),OR(L36="已完成",M36="已完成"))),"对接中",IF(OR(L36="进行中",L36="已完成",M36="进行中",M36="已完成"),"开发中",IF(AND(OR(J36="已完成",J36="不适用"),OR(K36="已完成",K36="不适用")),"待开发",IF(K36="进行中","UI设计中",IF(OR(J36="进行中",J36="已完成"),"原型中","未开始")))))))) -> 待开发
A37: CAP-036 | B37: 第一批 | C37: D10 | D37: 矿源备案 | E37: 物料档案 / 矿源备案 | F37: 干重扣减剩余量 | G37: 报备矿入库按干重扣减备案剩余（剩余−本次干重） | H37: POST /api/inbound | I37: P0 | J37: 已完成 | K37: 已完成 | L37: 未开始 | M37: 未开始 | N37: 未开始 | O37: 未开始 | P37: =IF(COUNTIF(J37:O37,"阻塞")>0,"阻塞",IF(COUNTIFS(J37:O37,"<>已完成",J37:O37,"<>不适用")=0,"已完成",IF(OR(O37="进行中",AND(OR(L37="已完成",L37="不适用"),OR(M37="已完成",M37="不适用"),OR(N37="已完成",N37="不适用"),AND(O37<>"已完成",O37<>"不适用"),OR(L37="已完成",M37="已完成",N37="已完成"))),"测试中",IF(OR(N37="进行中",AND(OR(L37="已完成",L37="不适用"),OR(M37="已完成",M37="不适用"),AND(N37<>"已完成",N37<>"不适用"),OR(L37="已完成",M37="已完成"))),"对接中",IF(OR(L37="进行中",L37="已完成",M37="进行中",M37="已完成"),"开发中",IF(AND(OR(J37="已完成",J37="不适用"),OR(K37="已完成",K37="不适用")),"待开发",IF(K37="进行中","UI设计中",IF(OR(J37="进行中",J37="已完成"),"原型中","未开始")))))))) -> 待开发
A38: CAP-037 | B38: 第一批 | C38: D10 | D38: 矿源备案 | E38: 物料档案 / 矿源备案 | F38: 用量阈值预警 | G38: 用量达系统参数阈值（默认 80%）触发预警 | H38: GET /api/inventory/alerts | I38: P0 | J38: 已完成 | K38: 已完成 | L38: 未开始 | M38: 未开始 | N38: 未开始 | O38: 未开始 | P38: =IF(COUNTIF(J38:O38,"阻塞")>0,"阻塞",IF(COUNTIFS(J38:O38,"<>已完成",J38:O38,"<>不适用")=0,"已完成",IF(OR(O38="进行中",AND(OR(L38="已完成",L38="不适用"),OR(M38="已完成",M38="不适用"),OR(N38="已完成",N38="不适用"),AND(O38<>"已完成",O38<>"不适用"),OR(L38="已完成",M38="已完成",N38="已完成"))),"测试中",IF(OR(N38="进行中",AND(OR(L38="已完成",L38="不适用"),OR(M38="已完成",M38="不适用"),AND(N38<>"已完成",N38<>"不适用"),OR(L38="已完成",M38="已完成"))),"对接中",IF(OR(L38="进行中",L38="已完成",M38="进行中",M38="已完成"),"开发中",IF(AND(OR(J38="已完成",J38="不适用"),OR(K38="已完成",K38="不适用")),"待开发",IF(K38="进行中","UI设计中",IF(OR(J38="进行中",J38="已完成"),"原型中","未开始")))))))) -> 待开发
A39: CAP-038 | B39: 第一批 | C39: D10 | D39: 矿源备案 | E39: 物料档案 / 矿源备案 | F39: 关联生产批次号 | G39: 备案详情展示关联生产批次号 | H39: GET /api/material-sources/filings | I39: P1 | J39: 已完成 | K39: 已完成 | L39: 未开始 | M39: 未开始 | N39: 未开始 | O39: 未开始 | P39: =IF(COUNTIF(J39:O39,"阻塞")>0,"阻塞",IF(COUNTIFS(J39:O39,"<>已完成",J39:O39,"<>不适用")=0,"已完成",IF(OR(O39="进行中",AND(OR(L39="已完成",L39="不适用"),OR(M39="已完成",M39="不适用"),OR(N39="已完成",N39="不适用"),AND(O39<>"已完成",O39<>"不适用"),OR(L39="已完成",M39="已完成",N39="已完成"))),"测试中",IF(OR(N39="进行中",AND(OR(L39="已完成",L39="不适用"),OR(M39="已完成",M39="不适用"),AND(N39<>"已完成",N39<>"不适用"),OR(L39="已完成",M39="已完成"))),"对接中",IF(OR(L39="进行中",L39="已完成",M39="进行中",M39="已完成"),"开发中",IF(AND(OR(J39="已完成",J39="不适用"),OR(K39="已完成",K39="不适用")),"待开发",IF(K39="进行中","UI设计中",IF(OR(J39="进行中",J39="已完成"),"原型中","未开始")))))))) -> 待开发
A40: CAP-039 | B40: 第二批 | C40: D20 | D40: 矿源备案 | E40: 库存查询 / 本票详情 | F40: 本票成品去向 | G40: 原料本票详情增加成品页：产量、库存、出库 | H40: GET /api/inventory/batches/{batchNo} | I40: P1 | J40: 已完成 | K40: 已完成 | L40: 未开始 | M40: 未开始 | N40: 未开始 | O40: 未开始 | P40: =IF(COUNTIF(J40:O40,"阻塞")>0,"阻塞",IF(COUNTIFS(J40:O40,"<>已完成",J40:O40,"<>不适用")=0,"已完成",IF(OR(O40="进行中",AND(OR(L40="已完成",L40="不适用"),OR(M40="已完成",M40="不适用"),OR(N40="已完成",N40="不适用"),AND(O40<>"已完成",O40<>"不适用"),OR(L40="已完成",M40="已完成",N40="已完成"))),"测试中",IF(OR(N40="进行中",AND(OR(L40="已完成",L40="不适用"),OR(M40="已完成",M40="不适用"),AND(N40<>"已完成",N40<>"不适用"),OR(L40="已完成",M40="已完成"))),"对接中",IF(OR(L40="进行中",L40="已完成",M40="进行中",M40="已完成"),"开发中",IF(AND(OR(J40="已完成",J40="不适用"),OR(K40="已完成",K40="不适用")),"待开发",IF(K40="进行中","UI设计中",IF(OR(J40="进行中",J40="已完成"),"原型中","未开始")))))))) -> 待开发
A41: CAP-040 | B41: 第一批 | C41: D10 | D41: 往来主体 | E41: 往来主体 | F41: 主体 CRUD | G41: 委托方、物流账册主体手工维护；编码、名称、角色、电话、状态、来源；不含统一社会信用代码 | H41: GET/POST /api/partners | I41: P0 | J41: 已完成 | K41: 已完成 | L41: 未开始 | M41: 未开始 | N41: 未开始 | O41: 未开始 | P41: =IF(COUNTIF(J41:O41,"阻塞")>0,"阻塞",IF(COUNTIFS(J41:O41,"<>已完成",J41:O41,"<>不适用")=0,"已完成",IF(OR(O41="进行中",AND(OR(L41="已完成",L41="不适用"),OR(M41="已完成",M41="不适用"),OR(N41="已完成",N41="不适用"),AND(O41<>"已完成",O41<>"不适用"),OR(L41="已完成",M41="已完成",N41="已完成"))),"测试中",IF(OR(N41="进行中",AND(OR(L41="已完成",L41="不适用"),OR(M41="已完成",M41="不适用"),AND(N41<>"已完成",N41<>"不适用"),OR(L41="已完成",M41="已完成"))),"对接中",IF(OR(L41="进行中",L41="已完成",M41="进行中",M41="已完成"),"开发中",IF(AND(OR(J41="已完成",J41="不适用"),OR(K41="已完成",K41="不适用")),"待开发",IF(K41="进行中","UI设计中",IF(OR(J41="进行中",J41="已完成"),"原型中","未开始")))))))) -> 待开发
A42: CAP-041 | B42: 第一批 | C42: D10 | D42: 往来主体 | E42: 往来主体 | F42: 委托方下拉 | G42: 五矿有色 / 广西金川 / 广西南国，贯穿出入库/移库/库存/生产 | H42: GET /api/partners/consignors | I42: P0 | J42: 已完成 | K42: 已完成 | L42: 未开始 | M42: 未开始 | N42: 未开始 | O42: 未开始 | P42: =IF(COUNTIF(J42:O42,"阻塞")>0,"阻塞",IF(COUNTIFS(J42:O42,"<>已完成",J42:O42,"<>不适用")=0,"已完成",IF(OR(O42="进行中",AND(OR(L42="已完成",L42="不适用"),OR(M42="已完成",M42="不适用"),OR(N42="已完成",N42="不适用"),AND(O42<>"已完成",O42<>"不适用"),OR(L42="已完成",M42="已完成",N42="已完成"))),"测试中",IF(OR(N42="进行中",AND(OR(L42="已完成",L42="不适用"),OR(M42="已完成",M42="不适用"),AND(N42<>"已完成",N42<>"不适用"),OR(L42="已完成",M42="已完成"))),"对接中",IF(OR(L42="进行中",L42="已完成",M42="进行中",M42="已完成"),"开发中",IF(AND(OR(J42="已完成",J42="不适用"),OR(K42="已完成",K42="不适用")),"待开发",IF(K42="进行中","UI设计中",IF(OR(J42="进行中",J42="已完成"),"原型中","未开始")))))))) -> 待开发
A43: CAP-042 | B43: 第二批 | C43: D20 | D43: 往来主体 | E43: 出库管理 | F43: 流向企业自动建档 | G43: 出库报关单「流向企业」字段自动写入往来主体，无需手工新建 | H43: POST /api/outbound | I43: P0 | J43: 已完成 | K43: 已完成 | L43: 未开始 | M43: 未开始 | N43: 未开始 | O43: 未开始 | P43: =IF(COUNTIF(J43:O43,"阻塞")>0,"阻塞",IF(COUNTIFS(J43:O43,"<>已完成",J43:O43,"<>不适用")=0,"已完成",IF(OR(O43="进行中",AND(OR(L43="已完成",L43="不适用"),OR(M43="已完成",M43="不适用"),OR(N43="已完成",N43="不适用"),AND(O43<>"已完成",O43<>"不适用"),OR(L43="已完成",M43="已完成",N43="已完成"))),"测试中",IF(OR(N43="进行中",AND(OR(L43="已完成",L43="不适用"),OR(M43="已完成",M43="不适用"),AND(N43<>"已完成",N43<>"不适用"),OR(L43="已完成",M43="已完成"))),"对接中",IF(OR(L43="进行中",L43="已完成",M43="进行中",M43="已完成"),"开发中",IF(AND(OR(J43="已完成",J43="不适用"),OR(K43="已完成",K43="不适用")),"待开发",IF(K43="进行中","UI设计中",IF(OR(J43="进行中",J43="已完成"),"原型中","未开始")))))))) -> 待开发
...

Sheet 页面对照
A1: 原型页面对照（便于评审走查与前后端分文件）
A3: 导航分组 | B3: 页面 ID | C3: 页面名称 | D3: 对应模块 | E3: 能力条数 | F3: 主要接口
A4: 概览 | B4: dashboard | C4: 可视化驾驶舱 | D4: 可视化驾驶舱 | E4: =COUNTIF(能力明细!D$2:D$154,"可视化驾驶舱") -> 11 | F4: GET /api/dashboard/cockpit；GET /api/floor-plans
A5: 基础数据 | B5: warehouses | C5: 仓库管理 | D5: 仓库管理 | E5: =COUNTIF(能力明细!D$2:D$154,"仓库管理") -> 3 | F5: GET/POST /api/warehouses
A6: 基础数据 | B6: stacks | C6: 堆位管理 | D6: 堆位管理 | E6: =COUNTIF(能力明细!D$2:D$154,"堆位管理") -> 7 | F6: GET/POST /api/warehouses/stacks；片区 PUT .../area-label
A7: 基础数据 | B7: materials | C7: 物料档案 / 矿源备案 | D7: 物料档案、矿源备案 | E7: =COUNTIF(能力明细!D$2:D$154,"物料档案")+COUNTIF(能力明细!D$2:D$154,"矿源备案") -> 14 | F7: GET/POST /api/materials；/api/material-sources/filings
A8: 基础数据 | B8: partners | C8: 往来主体 | D8: 往来主体 | E8: =COUNTIF(能力明细!D$2:D$154,"往来主体") -> 3 | F8: GET/POST /api/partners
A9: 基础数据 | B9: bonded | C9: 保税账册 | D9: 保税账册 | E9: =COUNTIF(能力明细!D$2:D$154,"保税账册") -> 6 | F9: GET/POST /api/bonded-books
A10: 基础数据 | B10: settings | C10: 系统设置（账号/角色/参数/平面图） | D10: 系统设置、平面图设置、公共框架 | E10: =COUNTIF(能力明细!D$2:D$154,"系统设置")+COUNTIF(能力明细!D$2:D$154,"平面图设置") -> 15 | F10: GET/POST /api/auth/users；roles；floor-plans
A11: 仓储作业 | B11: inbound | C11: 入库管理 | D11: 入库管理 | E11: =COUNTIF(能力明细!D$2:D$154,"入库管理") -> 13 | F11: GET/POST /api/inbound；POST /api/ocr/recognize
A12: 仓储作业 | B12: transfer | C12: 库内移库 | D12: 库内移库 | E12: =COUNTIF(能力明细!D$2:D$154,"库内移库") -> 8 | F12: GET/POST /api/transfers；POST /api/transfers/batch
A13: 仓储作业 | B13: inventory | C13: 库存查询 | D13: 库存查询 | E13: =COUNTIF(能力明细!D$2:D$154,"库存查询") -> 7 | F13: GET /api/inventory；batches/{batchNo}；ledger
A14: 仓储作业 | B14: stocktake | C14: 盘点管理 | D14: 盘点管理 | E14: =COUNTIF(能力明细!D$2:D$154,"盘点管理") -> 3 | F14: GET/POST /api/stocktakes；onhand-export
A15: 仓储作业 | B15: alert | C15: 库存预警 | D15: 库存预警 | E15: =COUNTIF(能力明细!D$2:D$154,"库存预警") -> 4 | F15: GET /api/inventory/alerts
A16: 仓储作业 | B16: outbound | C16: 出库管理 | D16: 出库管理 | E16: =COUNTIF(能力明细!D$2:D$154,"出库管理") -> 7 | F16: GET/POST /api/outbound
A17: 生产与关务 | B17: production | C17: 生产/完工 | D17: 生产完工 | E17: =COUNTIF(能力明细!D$2:D$154,"生产完工") -> 8 | F17: GET/POST /api/production
A18: 生产与关务 | B18: customs | C18: 关务保税 | D18: 关务保税 | E18: =COUNTIF(能力明细!D$2:D$154,"关务保税") -> 6 | F18: GET /api/customs/reconcile
A19: 生产与关务 | B19: ocr | C19: OCR识别 | D19: OCR识别 | E19: =COUNTIF(能力明细!D$2:D$154,"OCR识别") -> 7 | F19: POST /api/ocr/recognize
A20: 系统 | B20: integration | C20: 对外对接 | D20: 对外对接 | E20: =COUNTIF(能力明细!D$2:D$154,"对外对接") -> 7 | F20: /api/integrations/*
A21: 系统 | B21: audit | C21: 操作日志 | D21: 操作日志 | E21: =COUNTIF(能力明细!D$2:D$154,"操作日志") -> 3 | F21: GET /api/audit-logs
A22: — | B22: login | C22: 登录页 | D22: 公共框架 | E22: =COUNTIFS(能力明细!D$2:D$154,"公共框架",能力明细!E$2:E$154,"<>工程") -> 11 | F22: POST /api/auth/login
A23: — | B23: — | C23: 工程 / 信创 / 部署（无独立页面） | D23: 公共框架、部署交付 | E23: =COUNTIF(能力明细!D$2:D$154,"部署交付")+COUNTIFS(能力明细!D$2:D$154,"公共框架",能力明细!E$2:E$154,"工程") -> 10 | F23: 健康检查 / 部署脚本
A25: 走查建议：按本表页面顺序打开 wms/dist/index.html，对照「能力明细」中该模块全部 P0 项。关务员角色应能看到全部菜单；仓管员仅仓储作业相关。
